
Exception on /add [POST]
Traceback (most recent call last):
  File "C:\Users\janis\PycharmProjects\familytree\venv\lib\site-packages\flask\app.py", line 2051, in wsgi_app
    response = self.full_dispatch_request()
  File "C:\Users\janis\PycharmProjects\familytree\venv\lib\site-packages\flask\app.py", line 1501, in full_dispatch_request
    rv = self.handle_user_exception(e)
  File "C:\Users\janis\PycharmProjects\familytree\venv\lib\site-packages\flask\app.py", line 1499, in full_dispatch_request
    rv = self.dispatch_request()
  File "C:\Users\janis\PycharmProjects\familytree\venv\lib\site-packages\flask\app.py", line 1485, in dispatch_request
    return self.ensure_sync(self.view_functions[rule.endpoint])(**req.view_args)
  File "C:/Users/janis/PycharmProjects/familytree/manager.py", line 73, in add_person
    first_name = query_args.get('first_name').strip()
AttributeError: 'NoneType' object has no attribute 'get'
